<?xml version="1.0"?>
<robot name="revolver" xmlns:xacro="http://ros.org/wiki/xacro">

<material name="REVOLVER/Grey">
	<color rgba="${96/255} ${96/255} ${96/255} 1.0" />
</material>

<material name="REVOLVER/LightGrey">
	<color rgba="${192/255} ${192/255} ${192/255} 1.0" />
</material>

<material name="REVOLVER/Orange">
	<color rgba="${255/255} ${153/255} ${51/255} 1.0" />
</material>

<material name="REVOLVER/Green">
	<color rgba="${150/255} ${150/255} ${50/255} 1.0" />
</material>


<xacro:property name="c120" value="-0.5" />
<xacro:property name="s120" value="0.866025404" />
<xacro:property name="c45" value="0.707106781" />
<xacro:property name="s45" value="0.707106781" />
<xacro:property name="c90" value="0" />
<xacro:property name="s90" value="1" />
<xacro:property name="c22" value="0.923879533" />
<xacro:property name="s22" value="0.382683432" />


<xacro:macro name="barrel" params="name parent *origin">
	<joint name="${name}_joint" type="continuous">
		<xacro:insert_block name="origin" />
		<parent link="${parent}" />
		<child link="${name}_barrel" />
		<axis xyz="0 1 0" />
		<dynamics friction="0.001" damping="0.0001" />
	</joint>

	<link name="${name}_barrel">
		<visual>
			<origin rpy="0 0 0" xyz="0 0 0" />
			<geometry>
				<mesh filename="package://robot/model/meshes/barrel.stl" />
			</geometry>
			<material name="REVOLVER/Grey" />
		</visual>
		<collision>
			<geometry>
				<mesh filename="package://robot/model/meshes/barrel.stl" />
			</geometry>
		</collision>
		<inertial>
			<mass value="0.008" />
			<inertia ixx="0.00000075" ixy="0" ixz="0" iyy="0.00000037" iyz="0" izz="0.00000075" />
		</inertial>
	</link>

	 <transmission name="${name}_joint_trans">
		 <type>transmission_interface/SimpleTransmission</type>
		 <joint name="${name}_joint">
		 	<hardwareInterface>hardware_interface/EffortJointInterface</hardwareInterface>
		 </joint>
		 <actuator name="${name}_joint_motor">
		 	<mechanicalReduction>1</mechanicalReduction>
		 </actuator>
	 </transmission>
</xacro:macro>

<xacro:macro name="omniwheel" params="name parent *origin">
	<joint name="${name}" type="continuous" >
		<xacro:insert_block name="origin" />
		<parent link="${parent}" />
		<child link="${name}_frame" />
		<axis xyz="1 0 0" />
		<limit effort="100000." velocity="${2*pi}" />
		<dynamics friction="0.001" damping="0.0001" />
	</joint>

	<transmission name="${name}_trans">
		<type>transmission_interface/SimpleTransmission</type>
		<joint name="${name}">
			<hardwareInterface>hardware_interface/EffortJointInterface</hardwareInterface>
		</joint>
		<actuator name="${name}_motor">
			<mechanicalReduction>1</mechanicalReduction>
		</actuator>
	</transmission>


	<link name="${name}_frame">
		<visual>
			<origin  xyz="0 0 0" rpy="0 0 0" />
			<geometry>
				<mesh filename="package://robot/model/meshes/omniwheel.stl" />
			</geometry>
			<material name="REVOLVER/LightGrey" />
		</visual>
		<collision>
			<origin xyz="0 0 0" rpy=" 0 ${0.5*pi} 0" />
			<geometry>
				<cylinder length="0.01" radius="0.03" />
			</geometry>
			<material name="REVOLVER/Orange" />
		</collision>
		<inertial>
			<mass value="0.039" />
			<inertia ixx="0.00007188" ixy="0" ixz="0" iyy="0.00003634" iyz="0" izz="0.00003634" />
		</inertial>
	</link>

	<joint name="${name}_solid" type="fixed" >
		<parent link="${name}_frame" />
		<child link="${name}_frame_solid" />
		<origin  xyz="0.025 0 0" rpy="${22.5*pi/180} 0 0" />
	</joint>

	<link name="${name}_frame_solid">
		<visual>
			<origin  xyz="0 0 0" rpy="0 0 0" />
			<geometry>
				<mesh filename="package://robot/model/meshes/omniwheel.stl" />
			</geometry>
			<material name="REVOLVER/LightGrey" />
		</visual>
		<collision>
			<origin xyz="0 0 0" rpy=" 0 ${0.5*pi} 0" />
			<geometry>
				<cylinder length="0.01" radius="0.03" />
			</geometry>
			<material name="REVOLVER/Orange" />
		</collision>
		<inertial>
		<mass value="0.039" />
		<inertia ixx="0.00007188" ixy="0" ixz="0" iyy="0.00003634" iyz="0" izz="0.00003634" />
		</inertial>
	</link>

	<xacro:barrel name="${name}_barrel_1" parent="${name}_frame">
		<origin xyz="0 0 ${0.0525}" rpy="0 0 0" />
	</xacro:barrel>

	<xacro:barrel name="${name}_barrel_2" parent="${name}_frame">
		<origin xyz="0 ${c45*0.0525} ${s45*0.0525}" rpy="${-45*pi/180} 0 0" />
	</xacro:barrel>

	<xacro:barrel name="${name}_barrel_3" parent="${name}_frame">
		<origin xyz="${c90*0.0525} ${s90*0.0525} 0" rpy=" ${90*pi/180} 0 0" />
	</xacro:barrel>

	<xacro:barrel name="${name}_barrel_4" parent="${name}_frame">
		<origin xyz="0 ${s45*0.0525} ${-c45*0.0525}" rpy="${-135*pi/180} 0 0" />
	</xacro:barrel>

	<xacro:barrel name="${name}_barrel_5" parent="${name}_frame">
		<origin xyz="0 0 ${-0.0525}" rpy="0 0 0" />
	</xacro:barrel>

	<xacro:barrel name="${name}_barrel_6" parent="${name}_frame">
		<origin xyz="0 ${-s45*0.0525} ${-c45*0.0525}" rpy="${135*pi/180} 0 0" />
	</xacro:barrel>

	<xacro:barrel name="${name}_barrel_7" parent="${name}_frame">
		<origin xyz="${c90*0.0525} ${-s90*0.0525} 0" rpy=" ${-90*pi/180} 0 0" />
	</xacro:barrel>

	<xacro:barrel name="${name}_barrel_8" parent="${name}_frame">
		<origin xyz="0 ${-c45*0.0525} ${s45*0.0525}" rpy="${45*pi/180} 0 0" />
	</xacro:barrel>

	<xacro:barrel name="${name}_barrel_9" parent="${name}_frame_solid">
		<origin xyz="0 0 ${0.0525}" rpy="0 0 0" />
	</xacro:barrel>

	<xacro:barrel name="${name}_barrel_10" parent="${name}_frame_solid">
		<origin xyz="0 ${c45*0.0525} ${s45*0.0525}" rpy="${-45*pi/180} 0 0" />
	</xacro:barrel>

	<xacro:barrel name="${name}_barrel_11" parent="${name}_frame_solid">
		<origin xyz="${c90*0.0525} ${s90*0.0525} 0" rpy=" ${90*pi/180} 0 0" />
	</xacro:barrel>

	<xacro:barrel name="${name}_barrel_12" parent="${name}_frame_solid">
		<origin xyz="0 ${s45*0.0525} ${-c45*0.0525}" rpy="${-135*pi/180} 0 0" />
	</xacro:barrel>

	<xacro:barrel name="${name}_barrel_13" parent="${name}_frame_solid">
		<origin xyz="0 0 ${-0.0525}" rpy="0 0 0" />
	</xacro:barrel>

	<xacro:barrel name="${name}_barrel_14" parent="${name}_frame_solid">
		<origin xyz="0 ${-s45*0.0525} ${-c45*0.0525}" rpy="${135*pi/180} 0 0" />
	</xacro:barrel>

	<xacro:barrel name="${name}_barrel_15" parent="${name}_frame_solid">
		<origin xyz="${c90*0.0525} ${-s90*0.0525} 0" rpy=" ${-90*pi/180} 0 0" />
	</xacro:barrel>

	<xacro:barrel name="${name}_barrel_16" parent="${name}_frame_solid">
		<origin xyz="0 ${-c45*0.0525} ${s45*0.0525}" rpy="${45*pi/180} 0 0" />
	</xacro:barrel>
</xacro:macro>

<xacro:macro name="arm" params="name parent *origin">
	<joint name="${name}" type="fixed" >
		<xacro:insert_block name="origin" />
		<parent link="${parent}" />
		<child link="${name}_motor" />
		<axis xyz=" 0 0 0" />
	</joint>

	<link name="${name}_motor">
		<visual>
			<origin rpy="0 0 0" xyz="0 0 0 " />
			<geometry>
				<mesh filename="package://robot/model/meshes/motor.stl" scale="0.001 0.001 0.001" />
			</geometry>
			<material name="REVOLVER/LightGrey" />
		</visual>
		<collision>
			<origin xyz="0 0.14479 0.05685" rpy=" ${-112.5*pi/180} 0 0" />
			<geometry>
			<cylinder length="0.034" radius="0.016" />
			</geometry>
			<material name="REVOLVER/Orange" />
		</collision>
		<inertial>
			<mass value="0.1" />
			<inertia ixx="0.00000442" ixy="0" ixz="0" iyy="0.00000442" iyz="0" izz="0.00000063" />
		</inertial>
	</link>
	<joint name="${name}_shaft_joint" type="fixed">
		<parent link="${name}_motor" />
		<child link="${name}_motor_shaft" />
		<axis xyz="0 0 1" />
		<origin rpy= "${-112.5*pi/180} 0 0" xyz="0 0.12909 0.06335" />
	</joint>
	<link name="${name}_motor_shaft">
		<visual>
			<origin rpy="0 0 0" xyz="0 0 0" />
			<geometry>
				<mesh filename="package://robot/model/meshes/motor_shaft.stl" scale="0.001 0.001 0.001" />
			</geometry>
			<material name="REVOLVER/LightGrey" />
		</visual>
		<collision>
			<origin xyz="0 0 -0.00439 " rpy=" 0 0 0" />
			<geometry>
				<cylinder length="0.01" radius="0.0015" />
			</geometry>
			<material name="REVOLVER/Orange" />
		</collision>
		<inertial>
			<mass value="0.010" />
			<inertia ixx="0.00001" ixy="0" ixz="0" iyy="0.00001" iyz="0" izz="0.00001" />
		</inertial>
	</link>

	<transmission name="${name}_proximal_joint_trans">
		<type>transmission_interface/SimpleTransmission</type>
		<joint name="${name}_proximal_joint">
			<hardwareInterface>hardware_interface/PositionJointInterface</hardwareInterface>
		</joint>
		<actuator name="${name}_proximal_motor">
			<mechanicalReduction>1</mechanicalReduction>
		</actuator>
	</transmission>
	<joint name="${name}_proximal_joint" type="revolute">
		<parent link="${name}_motor_shaft" />
		<child link="${name}_proximal" />
		<axis xyz="0 0 1" />
		<origin rpy= "0 0 0" xyz="0 0 0" />
		<limit effort="100000" lower="${-45*pi/180}" upper="${45*pi/180}" velocity="${2*pi}" />
		<dynamics friction="0.01" damping="0.001" />
	</joint>
	<link name="${name}_proximal">
		<visual>
			<origin rpy="0 0 0" xyz="0 0 0" />
			<geometry>
				<mesh filename="package://robot/model/meshes/proximal.stl" scale="0.001 0.001 0.001" />
			</geometry>
			<material name="REVOLVER/Orange" />
		</visual>
		<collision>
			<geometry>
				<mesh filename="package://robot/model/meshes/proximal.stl" scale="0.001 0.001 0.001" />
			</geometry>
			<material name="REVOLVER/Orange" />
		</collision>
		<inertial>
			<mass value="0.025" />
			<inertia ixx="0.00000384" ixy="0" ixz="0.00000566" iyy="0.00002011" iyz="0" izz="0.00001923" />
		</inertial>
	</link>
	<joint name="${name}_distal_joint" type="continuous">
		<origin xyz="0 -0.05327 -0.01067" rpy= "${22.5*pi/180} 0 0" />
		<parent link="${name}_proximal" />
		<child link="${name}_distal" />
		<axis xyz="0 0 1" />
		<dynamics friction="0.01" damping="0.001" />
	</joint>
	<link name="${name}_distal">
		<visual>
			<origin rpy="0 0 0" xyz="0 0 0" />
			<geometry>
				<mesh filename="package://robot/model/meshes/distal.stl" scale="0.001 0.001 0.001" />
			</geometry>
			<material name="REVOLVER/Green" />
		</visual>
		<collision>
			<geometry>
				<mesh filename="package://robot/model/meshes/distal.stl" scale="0.001 0.001 0.001" />
			</geometry>
			<material name="REVOLVER/Orange" />
		</collision>
		<inertial>
			<mass value="0.025" />
			<inertia ixx="0.00001720" ixy="0" ixz="0" iyy="0.00000114" iyz="0.00000039" izz="0.00001736" />
		</inertial>
	</link>
</xacro:macro>

<xacro:macro name="propeller" params="name parent *origin">

	<joint name="${name}_propeller_joint" type="continuous">
		<xacro:insert_block name="origin" />
		<parent link="${parent}" />
		<child link="${name}_propeller" />
		<axis xyz="0 0 1" />
		<limit effort="999999" velocity="50000" />
		<dynamics friction="0.01" damping="0.001" />
	</joint>

	<link name="${name}_propeller">
		<visual>
			<origin xyz="0 0 0" rpy="0 0 0" />
			<geometry>
				<mesh filename="package://robot/model/meshes/propeller.stl" />
			</geometry>
			<material name="REVOLVER/LightGrey" />
		</visual>
		<collision>
			<origin xyz="0 0 0.07" rpy="0 0 0" />
			<geometry>
				<cylinder radius="0.125" length="0.01" />
			</geometry>
		</collision>
		<inertial>
			<origin xyz="0 0 0.07" rpy="0 0 0" />
			<mass value="0.0078" />
			<inertia ixx="0.00003179" ixy="-0.00000012" ixz="0" iyy="0.00000014" iyz="0" izz="0.00003186" />
		</inertial>
	</link>

	<transmission name="${name}_trans">
		<type>transmission_interface/SimpleTransmission</type>
		<joint name="${name}_propeller_joint">
			<hardwareInterface>hardware_interface/VelocityJointInterface</hardwareInterface>
		</joint>
		<actuator name="${name}_propeller_motor">
			<mechanicalReduction>1</mechanicalReduction>
		</actuator>
	</transmission>

	<!-- plugin to simulate the lift force by the helix -->
	<!--
		link_name: Name of the link affected by the group of lift/drag properties.
		air_density: Density of the fluid this model is suspended in.
		area: Surface area of the link.
		a0: The initial "alpha" or initial angle of attack. a0 is also the y-intercept of the alpha-lift coefficient curve.
		cla: The ratio of the coefficient of lift and alpha slope before stall. Slope of the first portion of the alpha-lift coefficient curve.
		cda: The ratio of the coefficient of drag and alpha slope before stall.
		cp: Center of pressure. The forces due to lift and drag will be applied here.
		forward: 3-vector representing the forward direction of motion in the link frame.
		upward: 3-vector representing the direction of lift or drag.
		alpha_stall: Angle of attack at stall point; the peak angle of attack.
		cla_stall: The ratio of coefficient of lift and alpha slope after stall. Slope of the second portion of the alpha-lift coefficient curve.
		cda_stall: The ratio of coefficient of drag and alpha slope after stall.
	-->
	<plugin name="${name}_blade_one" filename="libLiftDragPlugin.so">
		<a0>0.3</a0>
		<cla>1.4</cla>
		<cda>0.0</cda>
		<alpha_stall>1.2</alpha_stall>
		<cla_stall>-0.2</cla_stall>
		<cda_stall>-0.0</cda_stall>
		<cp>0 0.08 0.015</cp>
		<area>1</area>
		<air_density>1.2041</air_density>
		<forward>-1.0 0 0.0</forward>
		<upward>0.0 0 1.0</upward>
		<link_name>${name}_propeller</link_name>
	</plugin>
	<plugin name="${name}_blade_two" filename="libLiftDragPlugin.so">
		<a0>0.3</a0>
		<cla>1.4</cla>
		<cda>0.2</cda>
		<alpha_stall>1.2</alpha_stall>
		<cla_stall>-0.2</cla_stall>
		<cda_stall>-0.0</cda_stall>
		<cp>0 -0.08 0.015</cp>
		<area>1</area>
		<air_density>1.2041</air_density>
		<forward>1.0 0 0.0</forward>
		<upward>0.0 0 1.0</upward>
		<link_name>${name}_propeller</link_name>
	</plugin>

</xacro:macro>

<xacro:macro name="revolver" params="name">
	<link name="${name}_base">
		<visual>
			<origin xyz="0 0 0" rpy=" 0 0 ${2*pi/3}" />
			<geometry>
				<mesh filename="package://robot/model/meshes/main_body.stl" scale="0.001 0.001 0.001" />
			</geometry>
			<material name="REVOLVER/Grey" />
		</visual>
		<collision>
			<geometry>
				<cylinder length="0.05" radius="0.1" />
			</geometry>
		</collision>
		<inertial>
			<mass value="0.1" />
			<inertia ixx="0.000635774" ixy="0.0" ixz="0.0" iyy="0.000635799" iyz="0.0" izz="0.001183334" />
		</inertial>
	</link>

	<xacro:omniwheel name="${name}_wheel_1" parent="${name}_base">
		<origin xyz="0.238 0 0" rpy="0 0 0" />
	</xacro:omniwheel>
	<xacro:omniwheel name="${name}_wheel_2" parent="${name}_base">
		<origin xyz="${0.238*c120} ${0.238*s120} 0" rpy="0 0 ${120*pi/180}" />
	</xacro:omniwheel>
	<xacro:omniwheel name="${name}_wheel_3" parent="${name}_base">
		<origin xyz="${0.238*c120} ${-1*0.238*s120} 0" rpy="0 0 ${-120*pi/180}" />
	</xacro:omniwheel>

	<xacro:arm name="${name}_arm_1" parent="${name}_base">
		<origin xyz="0 0 0" rpy="0 0 ${30*pi/180}" />
	</xacro:arm>
	<xacro:arm name="${name}_arm_2" parent="${name}_base">
		<origin xyz="0 0 0" rpy="0 0 ${150*pi/180}" />
	</xacro:arm>
	<xacro:arm name="${name}_arm_3" parent="${name}_base">
		<origin xyz="0 0 0" rpy="0 0 ${-90*pi/180}" />
	</xacro:arm>

	<!-- temporary joint just for the platform not to fall down, later computed via Forward Kinematics -->
	<joint name="${name}_platform_joint" type="revolute">
		<parent link="${name}_arm_1_distal"/>
		<child link="${name}_platform"/>
		<origin xyz="0 0 -${s22*0.37}" rpy= "${90*pi/180} 0 0"/>
		<limit effort="100000" lower="${-45*pi/180}" upper="${45*pi/180}" velocity="${2*pi}"/>
		<dynamics friction="0.01" damping="0.001"/>
	</joint>
	<link name="${name}_platform">
		<visual>
			<origin rpy="0 0 0" xyz="0 0 0"/>
			<geometry>
				<mesh filename="package://robot/model/meshes/platform.stl" scale="0.001 0.001 0.001"/>
			</geometry>
			<material name="REVOLVER/Green" />
		</visual>
		<collision>
			<origin xyz="0 0 0.037" rpy="0 0 0" />
			<geometry>
				<cylinder length="0.050" radius="0.125"/>
			</geometry>
		</collision>
		<material name="REVOLVER/Green" />
		<inertial>
			<mass value="0.0679"/>
			<inertia ixx="0.00035045" ixy="0" ixz="0" iyy="0.00035046" iyz="0" izz="0.00041102"/>
		</inertial>
	</link>

	<xacro:propeller name="${name}_top" parent="${name}_platform">
		<origin xyz="0 0 0.005" rpy="0 0 0" />
	</xacro:propeller>
	<xacro:propeller name="${name}_bottom" parent="${name}_platform">
		<origin xyz="0 0 -0.065" rpy="0 0 0" />
	</xacro:propeller>
</xacro:macro>

</robot>
