<?xml version="1.0"?>
<robot name="week_2">

  <link name="omniwheel">
    <visual>
      <origin rpy="1.57075 0 0" xyz="-0.238 0 0.06250"/>
      <geometry>
        <mesh filename="package://urdf_tutorial/meshes/omniwheel.stl"/>
      </geometry>  
      <color rgba="0 0 0.8 1"/>
    </visual>
  </link>

    <link name="rodeta_1">
    <visual>
      <origin rpy="0 0 0" xyz="-0.238 0 0.01"/>
      <geometry>
        <mesh filename="package://urdf_tutorial/meshes/rodeta.stl"/>
      </geometry>  
      <color rgba="${255/255} ${108/255} ${10/255} 1.0"/>
    </visual>
  </link>

 <joint name="omniwheel_to_rodeta_1" type="continuous">
    <parent link="omniwheel"/>
    <child link="rodeta_1"/>
    <axis xyz="-0.328 0 0.01 "/>
    <origin xyz="0 1 0 "/>
  </joint>



    <link name="rodeta_2">
    <visual>
      <origin rpy="-0.785398 0 0" xyz="-0.238 -0.03712 0.02538"/>
      <geometry>
        <mesh filename="package://urdf_tutorial/meshes/rodeta.stl"/>
      </geometry>  
      <color rgba="0 0 0 1"/>
    </visual>
  </link>

 <joint name="omniwheel_to_rodeta_2" type="continuous">
    <parent link="omniwheel"/>
    <child link="rodeta_2"/>
    <axis xyz="-0.328 0.001 0"/> <!-- acabar de definir-->
    <origin xyz="0 -0.785398 0"/>   
  </joint>



   <link name="rodeta_3">
    <visual>
      <origin rpy="-1.570796 0 0" xyz="-0.238 -0.05250 0.06250"/>
      <geometry>
        <mesh filename="package://urdf_tutorial/meshes/rodeta.stl"/>
      </geometry>  
      <color rgba="0 0 0 1"/>
    </visual>
  </link>

 <joint name="omniwheel_to_rodeta_3" type="continuous">
    <parent link="omniwheel"/>
    <child link="rodeta_3"/>
    <axis xyz="-0.238 -0.05250 0"/>
    <origin xyz="0 0 1"/>
  </joint>



<link name="rodeta_4">
    <visual>
      <origin rpy="-2.35619 0 0" xyz="-0.238 -0.03712 0.09962"/>
      <geometry>
        <mesh filename="package://urdf_tutorial/meshes/rodeta.stl"/>
      </geometry>  
      <color rgba="0 0 0 1"/>
    </visual>
  </link>

 <joint name="omniwheel_to_rodeta_4" type="continuous">
    <parent link="omniwheel"/>
    <child link="rodeta_4"/>
    <axis xyz="-0.328  0.06250 0"/>     <!-- acabar de definir-->
    <origin xyz="0 -2.35619 0"/>   
  </joint>



    <link name="rodeta_5">
    <visual>
      <origin rpy="0 0 0" xyz="-0.238 0 0.115"/>
      <geometry>
        <mesh filename="package://urdf_tutorial/meshes/rodeta.stl"/>
      </geometry>  
      <color rgba="0 0 0 1"/>
    </visual>
  </link>

 <joint name="omniwheel_to_rodeta_5" type="continuous">
    <parent link="omniwheel"/>
    <child link="rodeta_5"/>
    <axis xyz="-0.238 0 0.115 "/>
    <origin xyz="0 1 0 "/>
  </joint>



<link name="rodeta_6">
    <visual>
      <origin rpy="2.35619 0 0" xyz="-0.238 0.03712 0.09962"/>
      <geometry>
        <mesh filename="package://urdf_tutorial/meshes/rodeta.stl"/>
      </geometry>  
      <color rgba="0 0 0 1"/>
    </visual>
  </link>

 <joint name="omniwheel_to_rodeta_6" type="continuous">
    <parent link="omniwheel"/>
    <child link="rodeta_6"/>
    <axis xyz="-0.238 0 0.06250"/>    <!-- acabar de definir-->
    <origin xyz="0 2.35619 0"/>  
  </joint>



 <link name="rodeta_7">
    <visual>
      <origin rpy="1.570796 0 0" xyz="-0.238 0.05250 0.06250"/>
      <geometry>
        <mesh filename="package://urdf_tutorial/meshes/rodeta.stl"/>
      </geometry>  
      <color rgba="0 0 0 1"/>
    </visual>
  </link>

 <joint name="omniwheel_to_rodeta_7" type="continuous">
    <parent link="omniwheel"/>
    <child link="rodeta_7"/>
    <axis xyz="-0.238 0.05250 0"/>
    <origin xyz="0 0 1"/>
  </joint>




     <link name="rodeta_8">
    <visual>
      <origin rpy="0.785398 0 0" xyz="-0.238 0.03712 0.02538"/>
      <geometry>
        <mesh filename="package://urdf_tutorial/meshes/rodeta.stl"/>
      </geometry>  
      <color rgba="0 0 0 1"/>
    </visual>
  </link>

 <joint name="omniwheel_to_rodeta_8" type="continuous">
    <parent link="omniwheel"/>
    <child link="rodeta_8"/>
    <axis xyz="0 0.785398 0.785398"/> <!-- acabar de definir-->
    <origin xyz="0 0.785398 0"/>  
  </joint>
</robot>


