  <joint name="rev1" type="revolute" >
    <parent link="base"/>
    <child link="fake_link"/>
     <origin xyz="0 0 0.01" rpy="0 0 ${-120*pi/180}"/>
    <axis xyz="1 0 0"/>
    <limit effort="100000." velocity="${2*pi}"/>
    <dynamics friction="0.01" damping="0.001"/>
  </joint>

<link name="fake_link" />

  <joint name="rev2" type="revolute" >
    <parent link="fake_link"/>
    <child link="motor_frame"/>
     <origin xyz="0 0 0.01" rpy="0 0 ${-120*pi/180}"/>
    <axis xyz="1 0 0"/>
    <limit effort="100000." velocity="${2*pi}"/>
    <dynamics friction="0.01" damping="0.001"/>
  </joint>

<link name="motor_frame" /> <!-- pot ser un mesh amb la geometria dels dos motors -->

  <joint name="motor1" type="continuous" >
    <parent link="motor_frame"/>
    <child link="helix1"/>
     <origin xyz="0 0 0.01" rpy="0 0 ${-120*pi/180}"/>
    <axis xyz="1 0 0"/>
    <limit effort="100000." velocity="${2*pi}"/>
    <dynamics friction="0.01" damping="0.001"/>
  </joint>
<link name="helix1" /> 


  <joint name="motor2" type="continuous" >
    <parent link="motor_frame"/>
    <child link="helix2"/>
     <origin xyz="0 0 0.01" rpy="0 0 ${-120*pi/180}"/>
    <axis xyz="1 0 0"/>
    <limit effort="100000." velocity="${2*pi}"/>
    <dynamics friction="0.01" damping="0.001"/>
  </joint>
<link name="helix2" /> 